<?xml version="1.0"?>
<robot xmlns:xacro="http://www.ros.org/wiki/xacro" >

    <!-- <xacro:include filename="inertial_macros.xacro"/> -->

    <xacro:property name="chassis_radius" value="0.175"/>
    <xacro:property name="chassis_height" value="0.085"/>
    <xacro:property name="chassis_mass" value="1.0"/> <xacro:property name="wheel_radius" value="0.035"/>
    <xacro:property name="wheel_width" value="0.015"/>
    <xacro:property name="wheel_mass" value="0.05"/>

    <xacro:property name="wheel_offset_y" value="0.1365"/>
    
    <xacro:property name="chassis_z_offset" value="0.0575"/> 
    
    <xacro:property name="caster_x_offset" value="0.145"/>


    <material name="white">
        <color rgba="1 1 1 1" />
    </material>
    <material name="orange">
        <color rgba="1 0.3 0.1 1" />
    </material>
    <material name="blue">
        <color rgba="0.2 0.2 1 1" />
    </material>
    <material name="black">
        <color rgba="0 0 0 1" />
    </material>

    <link name="base_link">
    </link>

    <joint name="chassis_joint" type="fixed">
        <parent link="base_link"/>
        <child link="chassis"/>
        <origin xyz="0 0 ${chassis_z_offset}"/>
    </joint>

    <link name="chassis">
        <visual>
            <origin xyz="0 0 0"/> 
            <geometry>
                <cylinder radius="${chassis_radius}" length="${chassis_height}"/>
            </geometry>
            <material name="white"/>
        </visual>

        <collision>
            <origin xyz="0 0 0"/> 
            <geometry>
                <cylinder radius="${chassis_radius}" length="${chassis_height}"/>
            </geometry>
        </collision>

        <!-- <xacro:inertial_cylinder mass="${chassis_mass}" length="${chassis_height}" radius="${chassis_radius}">
            <origin xyz="0 0 0" rpy="0 0 0"/>
        </xacro:inertial_cylinder> -->
    </link>

    <!-- <gazebo reference="chassis">
        <material>Gazebo/White</material>
    </gazebo> -->

    <joint name="left_wheel_joint" type="continuous">
        <parent link="base_link"/>
        <child link="left_wheel"/>
        <origin xyz="0 ${wheel_offset_y} ${wheel_radius}" rpy="-${pi/2} 0 0"/>
        <axis xyz="0 0 1"/>
    </joint> 

    <link name="left_wheel">
        <visual>
            <geometry>
                <cylinder radius="${wheel_radius}" length="${wheel_width}"/>
            </geometry>
            <material name="blue"/>
        </visual>
        <collision>
            <geometry>
                <cylinder radius="${wheel_radius}" length="${wheel_width}"/>
            </geometry>
        </collision>
        <!-- <xacro:inertial_cylinder mass="${wheel_mass}" length="${wheel_width}" radius="${wheel_radius}">
            <origin xyz="0 0 0" rpy="0 0 0"/>
        </xacro:inertial_cylinder> -->
    </link>

    <!-- <gazebo reference="left_wheel">
        <material>Gazebo/Blue</material>
    </gazebo> -->

    <joint name="right_wheel_joint" type="continuous">
        <parent link="base_link"/>
        <child link="right_wheel"/>
        <origin xyz="0 ${-wheel_offset_y} ${wheel_radius}" rpy="${pi/2} 0 0"/>
        <axis xyz="0 0 -1"/>
    </joint> 

    <link name="right_wheel">
        <visual>
            <geometry>
                <cylinder radius="${wheel_radius}" length="${wheel_width}"/>
            </geometry>
            <material name="blue"/>
        </visual>
        <collision>
            <geometry>
                <cylinder radius="${wheel_radius}" length="${wheel_width}"/>
            </geometry>
        </collision>
        <!-- <xacro:inertial_cylinder mass="${wheel_mass}" length="${wheel_width}" radius="${wheel_radius}">
            <origin xyz="0 0 0" rpy="0 0 0"/>
        </xacro:inertial_cylinder> -->
    </link>

    <!-- <gazebo reference="right_wheel">
        <material>Gazebo/Blue</material>
    </gazebo> -->

    <joint name="caster_wheel_joint" type="fixed">
        <parent link="chassis"/>
        <child link="caster_wheel"/>
        <origin xyz="${caster_x_offset} 0 ${-chassis_z_offset}"/>
    </joint>

    <link name="caster_wheel">
        <visual>
            <geometry>
                <sphere radius="0.015"/>
            </geometry>
            <material name="black"/>
        </visual>
        <collision>
            <geometry>
                <sphere radius="0.015"/>
            </geometry>
        </collision>
        <!-- <xacro:inertial_sphere mass="0.1" radius="0.015">
            <origin xyz="0 0 0" rpy="0 0 0" />
        </xacro:inertial_sphere> -->
    </link>

    <!-- <gazebo reference="caster_wheel">
        <material>Gazebo/Black</material>
        <mu1>0.001</mu1>
        <mu2>0.001</mu2>
    </gazebo> -->

</robot>